Traceback (most recent call last):
  File "/Users/aet/opt/anaconda3/lib/python3.7/site-packages/jupyter_cache/executors/utils.py", line 56, in single_nb_execution
    record_timing=False,
  File "/Users/aet/opt/anaconda3/lib/python3.7/site-packages/nbclient/client.py", line 1087, in execute
    return NotebookClient(nb=nb, resources=resources, km=km, **kwargs).execute()
  File "/Users/aet/opt/anaconda3/lib/python3.7/site-packages/nbclient/util.py", line 74, in wrapped
    return just_run(coro(*args, **kwargs))
  File "/Users/aet/opt/anaconda3/lib/python3.7/site-packages/nbclient/util.py", line 53, in just_run
    return loop.run_until_complete(coro)
  File "/Users/aet/opt/anaconda3/lib/python3.7/asyncio/base_events.py", line 583, in run_until_complete
    return future.result()
  File "/Users/aet/opt/anaconda3/lib/python3.7/site-packages/nbclient/client.py", line 541, in async_execute
    cell, index, execution_count=self.code_cells_executed + 1
  File "/Users/aet/opt/anaconda3/lib/python3.7/site-packages/nbclient/client.py", line 832, in async_execute_cell
    self._check_raise_for_error(cell, exec_reply)
  File "/Users/aet/opt/anaconda3/lib/python3.7/site-packages/nbclient/client.py", line 740, in _check_raise_for_error
    raise CellExecutionError.from_cell_and_msg(cell, exec_reply['content'])
nbclient.exceptions.CellExecutionError: An error occurred while executing the following cell:
------------------
df = pd.DataFrame(data=[['hello my blah is Ada'], ['hElLo mY blah IS Adam']],
                  columns=['strings'],
                  dtype='string')
df['strings'].apply(lambda x: x.lower().title().replace('blah', 'Name'))
------------------

[0;31m---------------------------------------------------------------------------[0m
[0;31mNameError[0m                                 Traceback (most recent call last)
[0;32m<ipython-input-40-826c161f9e25>[0m in [0;36m<module>[0;34m[0m
[0;32m----> 1[0;31m df = pd.DataFrame(data=[['hello my blah is Ada'], ['hElLo mY blah IS Adam']],
[0m[1;32m      2[0m                   [0mcolumns[0m[0;34m=[0m[0;34m[[0m[0;34m'strings'[0m[0;34m][0m[0;34m,[0m[0;34m[0m[0;34m[0m[0m
[1;32m      3[0m                   dtype='string')
[1;32m      4[0m [0mdf[0m[0;34m[[0m[0;34m'strings'[0m[0;34m][0m[0;34m.[0m[0mapply[0m[0;34m([0m[0;32mlambda[0m [0mx[0m[0;34m:[0m [0mx[0m[0;34m.[0m[0mlower[0m[0;34m([0m[0;34m)[0m[0;34m.[0m[0mtitle[0m[0;34m([0m[0;34m)[0m[0;34m.[0m[0mreplace[0m[0;34m([0m[0;34m'blah'[0m[0;34m,[0m [0;34m'Name'[0m[0;34m)[0m[0;34m)[0m[0;34m[0m[0;34m[0m[0m

[0;31mNameError[0m: name 'pd' is not defined
NameError: name 'pd' is not defined

