Traceback (most recent call last):
  File "/Users/aet/opt/anaconda3/envs/codeforecon/lib/python3.8/site-packages/jupyter_cache/executors/utils.py", line 51, in single_nb_execution
    executenb(
  File "/Users/aet/opt/anaconda3/envs/codeforecon/lib/python3.8/site-packages/nbclient/client.py", line 1087, in execute
    return NotebookClient(nb=nb, resources=resources, km=km, **kwargs).execute()
  File "/Users/aet/opt/anaconda3/envs/codeforecon/lib/python3.8/site-packages/nbclient/util.py", line 74, in wrapped
    return just_run(coro(*args, **kwargs))
  File "/Users/aet/opt/anaconda3/envs/codeforecon/lib/python3.8/site-packages/nbclient/util.py", line 53, in just_run
    return loop.run_until_complete(coro)
  File "/Users/aet/opt/anaconda3/envs/codeforecon/lib/python3.8/asyncio/base_events.py", line 616, in run_until_complete
    return future.result()
  File "/Users/aet/opt/anaconda3/envs/codeforecon/lib/python3.8/site-packages/nbclient/client.py", line 540, in async_execute
    await self.async_execute_cell(
  File "/Users/aet/opt/anaconda3/envs/codeforecon/lib/python3.8/site-packages/nbclient/client.py", line 832, in async_execute_cell
    self._check_raise_for_error(cell, exec_reply)
  File "/Users/aet/opt/anaconda3/envs/codeforecon/lib/python3.8/site-packages/nbclient/client.py", line 740, in _check_raise_for_error
    raise CellExecutionError.from_cell_and_msg(cell, exec_reply['content'])
nbclient.exceptions.CellExecutionError: An error occurred while executing the following cell:
------------------
from mizani.breaks import date_breaks
from mizani.formatters import date_format

g = (ggplot(df, aes(x='Name', y='Date', group='Name')) +
     geom_line(size=10, color='green') + coord_flip() +
     geom_text(df[df.variable=='Born'], aes(x='Name', y='Date', label='Name'),
               nudge_y=6500, color='white') +
     scale_y_date(breaks=date_breaks('20 years'), labels=date_format('%Y')) +
     theme(axis_text_y=element_blank())
    )
g
------------------

[0;31m---------------------------------------------------------------------------[0m
[0;31mValueError[0m                                Traceback (most recent call last)
[0;32m<ipython-input-97-033e90cf3a97>[0m in [0;36m<module>[0;34m[0m
[1;32m      4[0m g = (ggplot(df, aes(x='Name', y='Date', group='Name')) +
[1;32m      5[0m      [0mgeom_line[0m[0;34m([0m[0msize[0m[0;34m=[0m[0;36m10[0m[0;34m,[0m [0mcolor[0m[0;34m=[0m[0;34m'green'[0m[0;34m)[0m [0;34m+[0m [0mcoord_flip[0m[0;34m([0m[0;34m)[0m [0;34m+[0m[0;34m[0m[0;34m[0m[0m
[0;32m----> 6[0;31m      geom_text(df[df.variable=='Born'], aes(x='Name', y='Date', label='Name'),
[0m[1;32m      7[0m                nudge_y=6500, color='white') +
[1;32m      8[0m      [0mscale_y_date[0m[0;34m([0m[0mbreaks[0m[0;34m=[0m[0mdate_breaks[0m[0;34m([0m[0;34m'20 years'[0m[0;34m)[0m[0;34m,[0m [0mlabels[0m[0;34m=[0m[0mdate_format[0m[0;34m([0m[0;34m'%Y'[0m[0;34m)[0m[0;34m)[0m [0;34m+[0m[0;34m[0m[0;34m[0m[0m

[0;32m~/opt/anaconda3/envs/codeforecon/lib/python3.8/site-packages/plotnine/geoms/geom_text.py[0m in [0;36m__init__[0;34m(self, mapping, data, **kwargs)[0m
[1;32m    104[0m [0;34m[0m[0m
[1;32m    105[0m         [0;31m# Accomodate the old names[0m[0;34m[0m[0;34m[0m[0;34m[0m[0m
[0;32m--> 106[0;31m         [0;32mif[0m [0mmapping[0m [0;32mand[0m [0;34m'hjust'[0m [0;32min[0m [0mmapping[0m[0;34m:[0m[0;34m[0m[0;34m[0m[0m
[0m[1;32m    107[0m             [0mmapping[0m[0;34m[[0m[0;34m'ha'[0m[0;34m][0m [0;34m=[0m [0mmapping[0m[0;34m.[0m[0mpop[0m[0;34m([0m[0;34m'hjust'[0m[0;34m)[0m[0;34m[0m[0;34m[0m[0m
[1;32m    108[0m [0;34m[0m[0m

[0;32m~/opt/anaconda3/envs/codeforecon/lib/python3.8/site-packages/pandas/core/generic.py[0m in [0;36m__nonzero__[0;34m(self)[0m
[1;32m   1437[0m     [0;34m@[0m[0mfinal[0m[0;34m[0m[0;34m[0m[0m
[1;32m   1438[0m     [0;32mdef[0m [0m__nonzero__[0m[0;34m([0m[0mself[0m[0;34m)[0m[0;34m:[0m[0;34m[0m[0;34m[0m[0m
[0;32m-> 1439[0;31m         raise ValueError(
[0m[1;32m   1440[0m             [0;34mf"The truth value of a {type(self).__name__} is ambiguous. "[0m[0;34m[0m[0;34m[0m[0m
[1;32m   1441[0m             [0;34m"Use a.empty, a.bool(), a.item(), a.any() or a.all()."[0m[0;34m[0m[0;34m[0m[0m

[0;31mValueError[0m: The truth value of a DataFrame is ambiguous. Use a.empty, a.bool(), a.item(), a.any() or a.all().
ValueError: The truth value of a DataFrame is ambiguous. Use a.empty, a.bool(), a.item(), a.any() or a.all().

