Traceback (most recent call last):
  File "/Users/aet/opt/anaconda3/envs/codeforecon/lib/python3.8/site-packages/jupyter_cache/executors/utils.py", line 51, in single_nb_execution
    executenb(
  File "/Users/aet/opt/anaconda3/envs/codeforecon/lib/python3.8/site-packages/nbclient/client.py", line 1087, in execute
    return NotebookClient(nb=nb, resources=resources, km=km, **kwargs).execute()
  File "/Users/aet/opt/anaconda3/envs/codeforecon/lib/python3.8/site-packages/nbclient/util.py", line 74, in wrapped
    return just_run(coro(*args, **kwargs))
  File "/Users/aet/opt/anaconda3/envs/codeforecon/lib/python3.8/site-packages/nbclient/util.py", line 53, in just_run
    return loop.run_until_complete(coro)
  File "/Users/aet/opt/anaconda3/envs/codeforecon/lib/python3.8/asyncio/base_events.py", line 616, in run_until_complete
    return future.result()
  File "/Users/aet/opt/anaconda3/envs/codeforecon/lib/python3.8/site-packages/nbclient/client.py", line 540, in async_execute
    await self.async_execute_cell(
  File "/Users/aet/opt/anaconda3/envs/codeforecon/lib/python3.8/site-packages/nbclient/client.py", line 832, in async_execute_cell
    self._check_raise_for_error(cell, exec_reply)
  File "/Users/aet/opt/anaconda3/envs/codeforecon/lib/python3.8/site-packages/nbclient/client.py", line 740, in _check_raise_for_error
    raise CellExecutionError.from_cell_and_msg(cell, exec_reply['content'])
nbclient.exceptions.CellExecutionError: An error occurred while executing the following cell:
------------------
labels = barley['site'].unique()
y = np.arange(len(labels))  # the label locations
width = 0.35  # the width (or height) of the bars

fig, ax = plt.subplots()
ax.barh(y, barley.loc[barley['year'] == 1931, 'yield'], width, label='1931')
ax.barh(y, barley.loc[barley['year'] == 1932, 'yield'], width, label='1932', left=barley.loc[barley['year'] == 1931, 'yield'])

# Add some text for labels, title and custom x-axis tick labels, etc.
ax.set_xlabel('Yield')
ax.set_yticks(x)
ax.set_yticklabels(labels)
ax.legend(frameon=False)
plt.show()
------------------

[0;31m---------------------------------------------------------------------------[0m
[0;31mNameError[0m                                 Traceback (most recent call last)
[0;32m<ipython-input-26-0523b6e46691>[0m in [0;36m<module>[0;34m[0m
[1;32m      9[0m [0;31m# Add some text for labels, title and custom x-axis tick labels, etc.[0m[0;34m[0m[0;34m[0m[0;34m[0m[0m
[1;32m     10[0m [0max[0m[0;34m.[0m[0mset_xlabel[0m[0;34m([0m[0;34m'Yield'[0m[0;34m)[0m[0;34m[0m[0;34m[0m[0m
[0;32m---> 11[0;31m [0max[0m[0;34m.[0m[0mset_yticks[0m[0;34m([0m[0mx[0m[0;34m)[0m[0;34m[0m[0;34m[0m[0m
[0m[1;32m     12[0m [0max[0m[0;34m.[0m[0mset_yticklabels[0m[0;34m([0m[0mlabels[0m[0;34m)[0m[0;34m[0m[0;34m[0m[0m
[1;32m     13[0m [0max[0m[0;34m.[0m[0mlegend[0m[0;34m([0m[0mframeon[0m[0;34m=[0m[0;32mFalse[0m[0;34m)[0m[0;34m[0m[0;34m[0m[0m

[0;31mNameError[0m: name 'x' is not defined
NameError: name 'x' is not defined

