Traceback (most recent call last):
  File "/Users/aet/opt/anaconda3/envs/codeforecon/lib/python3.8/site-packages/jupyter_cache/executors/utils.py", line 51, in single_nb_execution
    executenb(
  File "/Users/aet/opt/anaconda3/envs/codeforecon/lib/python3.8/site-packages/nbclient/client.py", line 1087, in execute
    return NotebookClient(nb=nb, resources=resources, km=km, **kwargs).execute()
  File "/Users/aet/opt/anaconda3/envs/codeforecon/lib/python3.8/site-packages/nbclient/util.py", line 74, in wrapped
    return just_run(coro(*args, **kwargs))
  File "/Users/aet/opt/anaconda3/envs/codeforecon/lib/python3.8/site-packages/nbclient/util.py", line 53, in just_run
    return loop.run_until_complete(coro)
  File "/Users/aet/opt/anaconda3/envs/codeforecon/lib/python3.8/asyncio/base_events.py", line 616, in run_until_complete
    return future.result()
  File "/Users/aet/opt/anaconda3/envs/codeforecon/lib/python3.8/site-packages/nbclient/client.py", line 540, in async_execute
    await self.async_execute_cell(
  File "/Users/aet/opt/anaconda3/envs/codeforecon/lib/python3.8/site-packages/nbclient/client.py", line 832, in async_execute_cell
    self._check_raise_for_error(cell, exec_reply)
  File "/Users/aet/opt/anaconda3/envs/codeforecon/lib/python3.8/site-packages/nbclient/client.py", line 740, in _check_raise_for_error
    raise CellExecutionError.from_cell_and_msg(cell, exec_reply['content'])
nbclient.exceptions.CellExecutionError: An error occurred while executing the following cell:
------------------
User(signup_ts='broken', friends=[1, 2, 'not number'])
------------------

[0;31m---------------------------------------------------------------------------[0m
[0;31mValidationError[0m                           Traceback (most recent call last)
[0;32m<ipython-input-15-7a13cdd5b253>[0m in [0;36m<module>[0;34m[0m
[0;32m----> 1[0;31m [0mUser[0m[0;34m([0m[0msignup_ts[0m[0;34m=[0m[0;34m'broken'[0m[0;34m,[0m [0mfriends[0m[0;34m=[0m[0;34m[[0m[0;36m1[0m[0;34m,[0m [0;36m2[0m[0;34m,[0m [0;34m'not number'[0m[0;34m][0m[0;34m)[0m[0;34m[0m[0;34m[0m[0m
[0m
[0;32m~/opt/anaconda3/envs/codeforecon/lib/python3.8/site-packages/pydantic/main.cpython-38-darwin.so[0m in [0;36mpydantic.main.BaseModel.__init__[0;34m()[0m

[0;31mValidationError[0m: 3 validation errors for User
id
  field required (type=value_error.missing)
signup_ts
  invalid datetime format (type=value_error.datetime)
friends -> 2
  value is not a valid integer (type=type_error.integer)
ValidationError: 3 validation errors for User
id
  field required (type=value_error.missing)
signup_ts
  invalid datetime format (type=value_error.datetime)
friends -> 2
  value is not a valid integer (type=type_error.integer)

