Traceback (most recent call last):
  File "/Users/arthurturrell/opt/anaconda3/envs/codeforecon/lib/python3.8/site-packages/jupyter_cache/executors/utils.py", line 51, in single_nb_execution
    executenb(
  File "/Users/arthurturrell/opt/anaconda3/envs/codeforecon/lib/python3.8/site-packages/nbclient/client.py", line 1107, in execute
    return NotebookClient(nb=nb, resources=resources, km=km, **kwargs).execute()
  File "/Users/arthurturrell/opt/anaconda3/envs/codeforecon/lib/python3.8/site-packages/nbclient/util.py", line 74, in wrapped
    return just_run(coro(*args, **kwargs))
  File "/Users/arthurturrell/opt/anaconda3/envs/codeforecon/lib/python3.8/site-packages/nbclient/util.py", line 53, in just_run
    return loop.run_until_complete(coro)
  File "/Users/arthurturrell/opt/anaconda3/envs/codeforecon/lib/python3.8/asyncio/base_events.py", line 616, in run_until_complete
    return future.result()
  File "/Users/arthurturrell/opt/anaconda3/envs/codeforecon/lib/python3.8/site-packages/nbclient/client.py", line 553, in async_execute
    await self.async_execute_cell(
  File "/Users/arthurturrell/opt/anaconda3/envs/codeforecon/lib/python3.8/site-packages/nbclient/client.py", line 852, in async_execute_cell
    self._check_raise_for_error(cell, exec_reply)
  File "/Users/arthurturrell/opt/anaconda3/envs/codeforecon/lib/python3.8/site-packages/nbclient/client.py", line 760, in _check_raise_for_error
    raise CellExecutionError.from_cell_and_msg(cell, exec_reply_content)
nbclient.exceptions.CellExecutionError: An error occurred while executing the following cell:
------------------
import pandas as pd
import os
import numpy as np

# Set seed for reproducibility
np.random.seed(10)
# Set max rows displayed for readability
pd.set_option('display.max_rows', 6)
# Plot settings
plt.style.use('plot_style.txt')

# Read in data
df = pd.read_pickle(os.path.join('data', 'starwars.pickle'))
# Check info about dataframe
df.info()
------------------

[0;31m---------------------------------------------------------------------------[0m
[0;31mNameError[0m                                 Traceback (most recent call last)
[0;32m<ipython-input-1-588b829598a4>[0m in [0;36m<module>[0;34m[0m
[1;32m      8[0m [0mpd[0m[0;34m.[0m[0mset_option[0m[0;34m([0m[0;34m'display.max_rows'[0m[0;34m,[0m [0;36m6[0m[0;34m)[0m[0;34m[0m[0;34m[0m[0m
[1;32m      9[0m [0;31m# Plot settings[0m[0;34m[0m[0;34m[0m[0;34m[0m[0m
[0;32m---> 10[0;31m [0mplt[0m[0;34m.[0m[0mstyle[0m[0;34m.[0m[0muse[0m[0;34m([0m[0;34m'plot_style.txt'[0m[0;34m)[0m[0;34m[0m[0;34m[0m[0m
[0m[1;32m     11[0m [0;34m[0m[0m
[1;32m     12[0m [0;31m# Read in data[0m[0;34m[0m[0;34m[0m[0;34m[0m[0m

[0;31mNameError[0m: name 'plt' is not defined
NameError: name 'plt' is not defined

