Traceback (most recent call last):
  File "/Users/aet/opt/anaconda3/envs/codeforecon/lib/python3.8/site-packages/jupyter_cache/executors/utils.py", line 51, in single_nb_execution
    executenb(
  File "/Users/aet/opt/anaconda3/envs/codeforecon/lib/python3.8/site-packages/nbclient/client.py", line 1117, in execute
    return NotebookClient(nb=nb, resources=resources, km=km, **kwargs).execute()
  File "/Users/aet/opt/anaconda3/envs/codeforecon/lib/python3.8/site-packages/nbclient/util.py", line 78, in wrapped
    return just_run(coro(*args, **kwargs))
  File "/Users/aet/opt/anaconda3/envs/codeforecon/lib/python3.8/site-packages/nbclient/util.py", line 57, in just_run
    return loop.run_until_complete(coro)
  File "/Users/aet/opt/anaconda3/envs/codeforecon/lib/python3.8/asyncio/base_events.py", line 616, in run_until_complete
    return future.result()
  File "/Users/aet/opt/anaconda3/envs/codeforecon/lib/python3.8/site-packages/nbclient/client.py", line 558, in async_execute
    await self.async_execute_cell(
  File "/Users/aet/opt/anaconda3/envs/codeforecon/lib/python3.8/site-packages/nbclient/client.py", line 862, in async_execute_cell
    self._check_raise_for_error(cell, exec_reply)
  File "/Users/aet/opt/anaconda3/envs/codeforecon/lib/python3.8/site-packages/nbclient/client.py", line 765, in _check_raise_for_error
    raise CellExecutionError.from_cell_and_msg(cell, exec_reply_content)
nbclient.exceptions.CellExecutionError: An error occurred while executing the following cell:
------------------
import numpy as np
from scipy import stats
import matplotlib.pyplot as plt
import pandas as pd
import pingouin as pg
import statsmodels.formula.api as smf
from numpy.random import Generator, PCG64

# Set seed for random numbers
seed_for_prng = 78557
prng = Generator(PCG64(seed_for_prng))
------------------

[0;31m---------------------------------------------------------------------------[0m
[0;31mModuleNotFoundError[0m                       Traceback (most recent call last)
[0;32m/var/folders/x6/ffnr59f116l96_y0q0bjfz7c0000gn/T/ipykernel_63005/3182939853.py[0m in [0;36m<module>[0;34m[0m
[1;32m      3[0m [0;32mimport[0m [0mmatplotlib[0m[0;34m.[0m[0mpyplot[0m [0;32mas[0m [0mplt[0m[0;34m[0m[0;34m[0m[0m
[1;32m      4[0m [0;32mimport[0m [0mpandas[0m [0;32mas[0m [0mpd[0m[0;34m[0m[0;34m[0m[0m
[0;32m----> 5[0;31m [0;32mimport[0m [0mpingouin[0m [0;32mas[0m [0mpg[0m[0;34m[0m[0;34m[0m[0m
[0m[1;32m      6[0m [0;32mimport[0m [0mstatsmodels[0m[0;34m.[0m[0mformula[0m[0;34m.[0m[0mapi[0m [0;32mas[0m [0msmf[0m[0;34m[0m[0;34m[0m[0m
[1;32m      7[0m [0;32mfrom[0m [0mnumpy[0m[0;34m.[0m[0mrandom[0m [0;32mimport[0m [0mGenerator[0m[0;34m,[0m [0mPCG64[0m[0;34m[0m[0;34m[0m[0m

[0;31mModuleNotFoundError[0m: No module named 'pingouin'
ModuleNotFoundError: No module named 'pingouin'

