Traceback (most recent call last):
  File "/Users/arthurturrell/opt/anaconda3/envs/codeforecon/lib/python3.8/site-packages/jupyter_cache/executors/utils.py", line 51, in single_nb_execution
    executenb(
  File "/Users/arthurturrell/opt/anaconda3/envs/codeforecon/lib/python3.8/site-packages/nbclient/client.py", line 1107, in execute
    return NotebookClient(nb=nb, resources=resources, km=km, **kwargs).execute()
  File "/Users/arthurturrell/opt/anaconda3/envs/codeforecon/lib/python3.8/site-packages/nbclient/util.py", line 74, in wrapped
    return just_run(coro(*args, **kwargs))
  File "/Users/arthurturrell/opt/anaconda3/envs/codeforecon/lib/python3.8/site-packages/nbclient/util.py", line 53, in just_run
    return loop.run_until_complete(coro)
  File "/Users/arthurturrell/opt/anaconda3/envs/codeforecon/lib/python3.8/asyncio/base_events.py", line 616, in run_until_complete
    return future.result()
  File "/Users/arthurturrell/opt/anaconda3/envs/codeforecon/lib/python3.8/site-packages/nbclient/client.py", line 553, in async_execute
    await self.async_execute_cell(
  File "/Users/arthurturrell/opt/anaconda3/envs/codeforecon/lib/python3.8/site-packages/nbclient/client.py", line 852, in async_execute_cell
    self._check_raise_for_error(cell, exec_reply)
  File "/Users/arthurturrell/opt/anaconda3/envs/codeforecon/lib/python3.8/site-packages/nbclient/client.py", line 760, in _check_raise_for_error
    raise CellExecutionError.from_cell_and_msg(cell, exec_reply_content)
nbclient.exceptions.CellExecutionError: An error occurred while executing the following cell:
------------------
# TODO hide cell
# Set max rows displayed for readability
pd.set_option('display.max_rows', 6)
# Plot settings
plt.style.use('plot_style.txt')
# For this chapter, some bespoke settings:
plt.style.use({'axes.autolimit_mode': 'data', 'patch.linewidth': 0.2,
               'figure.figsize': (10, 8), 'dpi': 150})
# TODO: for this chapter, turn off spines etc by default?
------------------

[0;31m---------------------------------------------------------------------------[0m
[0;31mKeyError[0m                                  Traceback (most recent call last)
[0;32m~/opt/anaconda3/envs/codeforecon/lib/python3.8/site-packages/matplotlib/__init__.py[0m in [0;36m__setitem__[0;34m(self, key, val)[0m
[1;32m    676[0m             [0;32mtry[0m[0;34m:[0m[0;34m[0m[0;34m[0m[0m
[0;32m--> 677[0;31m                 [0mcval[0m [0;34m=[0m [0mself[0m[0;34m.[0m[0mvalidate[0m[0;34m[[0m[0mkey[0m[0;34m][0m[0;34m([0m[0mval[0m[0;34m)[0m[0;34m[0m[0;34m[0m[0m
[0m[1;32m    678[0m             [0;32mexcept[0m [0mValueError[0m [0;32mas[0m [0mve[0m[0;34m:[0m[0;34m[0m[0;34m[0m[0m

[0;31mKeyError[0m: 'dpi'

The above exception was the direct cause of the following exception:

[0;31mKeyError[0m                                  Traceback (most recent call last)
[0;32m<ipython-input-2-abcd0c38a98d>[0m in [0;36m<module>[0;34m[0m
[1;32m      5[0m [0mplt[0m[0;34m.[0m[0mstyle[0m[0;34m.[0m[0muse[0m[0;34m([0m[0;34m'plot_style.txt'[0m[0;34m)[0m[0;34m[0m[0;34m[0m[0m
[1;32m      6[0m [0;31m# For this chapter, some bespoke settings:[0m[0;34m[0m[0;34m[0m[0;34m[0m[0m
[0;32m----> 7[0;31m plt.style.use({'axes.autolimit_mode': 'data', 'patch.linewidth': 0.2,
[0m[1;32m      8[0m                'figure.figsize': (10, 8), 'dpi': 150})
[1;32m      9[0m [0;31m# TODO: for this chapter, turn off spines etc by default?[0m[0;34m[0m[0;34m[0m[0;34m[0m[0m

[0;32m~/opt/anaconda3/envs/codeforecon/lib/python3.8/site-packages/matplotlib/style/core.py[0m in [0;36muse[0;34m(style)[0m
[1;32m    109[0m     [0;32mfor[0m [0mstyle[0m [0;32min[0m [0mstyles[0m[0;34m:[0m[0;34m[0m[0;34m[0m[0m
[1;32m    110[0m         [0;32mif[0m [0;32mnot[0m [0misinstance[0m[0;34m([0m[0mstyle[0m[0;34m,[0m [0;34m([0m[0mstr[0m[0;34m,[0m [0mPath[0m[0;34m)[0m[0;34m)[0m[0;34m:[0m[0;34m[0m[0;34m[0m[0m
[0;32m--> 111[0;31m             [0m_apply_style[0m[0;34m([0m[0mstyle[0m[0;34m)[0m[0;34m[0m[0;34m[0m[0m
[0m[1;32m    112[0m         [0;32melif[0m [0mstyle[0m [0;34m==[0m [0;34m'default'[0m[0;34m:[0m[0;34m[0m[0;34m[0m[0m
[1;32m    113[0m             [0;31m# Deprecation warnings were already handled when creating[0m[0;34m[0m[0;34m[0m[0;34m[0m[0m

[0;32m~/opt/anaconda3/envs/codeforecon/lib/python3.8/site-packages/matplotlib/style/core.py[0m in [0;36m_apply_style[0;34m(d, warn)[0m
[1;32m     63[0m [0;34m[0m[0m
[1;32m     64[0m [0;32mdef[0m [0m_apply_style[0m[0;34m([0m[0md[0m[0;34m,[0m [0mwarn[0m[0;34m=[0m[0;32mTrue[0m[0;34m)[0m[0;34m:[0m[0;34m[0m[0;34m[0m[0m
[0;32m---> 65[0;31m     [0mmpl[0m[0;34m.[0m[0mrcParams[0m[0;34m.[0m[0mupdate[0m[0;34m([0m[0m_remove_blacklisted_style_params[0m[0;34m([0m[0md[0m[0;34m,[0m [0mwarn[0m[0;34m=[0m[0mwarn[0m[0;34m)[0m[0;34m)[0m[0;34m[0m[0;34m[0m[0m
[0m[1;32m     66[0m [0;34m[0m[0m
[1;32m     67[0m [0;34m[0m[0m

[0;32m~/opt/anaconda3/envs/codeforecon/lib/python3.8/_collections_abc.py[0m in [0;36mupdate[0;34m(self, other, **kwds)[0m
[1;32m    830[0m         [0;32mif[0m [0misinstance[0m[0;34m([0m[0mother[0m[0;34m,[0m [0mMapping[0m[0;34m)[0m[0;34m:[0m[0;34m[0m[0;34m[0m[0m
[1;32m    831[0m             [0;32mfor[0m [0mkey[0m [0;32min[0m [0mother[0m[0;34m:[0m[0;34m[0m[0;34m[0m[0m
[0;32m--> 832[0;31m                 [0mself[0m[0;34m[[0m[0mkey[0m[0;34m][0m [0;34m=[0m [0mother[0m[0;34m[[0m[0mkey[0m[0;34m][0m[0;34m[0m[0;34m[0m[0m
[0m[1;32m    833[0m         [0;32melif[0m [0mhasattr[0m[0;34m([0m[0mother[0m[0;34m,[0m [0;34m"keys"[0m[0;34m)[0m[0;34m:[0m[0;34m[0m[0;34m[0m[0m
[1;32m    834[0m             [0;32mfor[0m [0mkey[0m [0;32min[0m [0mother[0m[0;34m.[0m[0mkeys[0m[0;34m([0m[0;34m)[0m[0;34m:[0m[0;34m[0m[0;34m[0m[0m

[0;32m~/opt/anaconda3/envs/codeforecon/lib/python3.8/site-packages/matplotlib/__init__.py[0m in [0;36m__setitem__[0;34m(self, key, val)[0m
[1;32m    680[0m             [0mdict[0m[0;34m.[0m[0m__setitem__[0m[0;34m([0m[0mself[0m[0;34m,[0m [0mkey[0m[0;34m,[0m [0mcval[0m[0;34m)[0m[0;34m[0m[0;34m[0m[0m
[1;32m    681[0m         [0;32mexcept[0m [0mKeyError[0m [0;32mas[0m [0merr[0m[0;34m:[0m[0;34m[0m[0;34m[0m[0m
[0;32m--> 682[0;31m             raise KeyError(
[0m[1;32m    683[0m                 [0;34mf"{key} is not a valid rc parameter (see rcParams.keys() for "[0m[0;34m[0m[0;34m[0m[0m
[1;32m    684[0m                 f"a list of valid parameters)") from err

[0;31mKeyError[0m: 'dpi is not a valid rc parameter (see rcParams.keys() for a list of valid parameters)'
KeyError: 'dpi is not a valid rc parameter (see rcParams.keys() for a list of valid parameters)'

