Traceback (most recent call last):
  File "/Users/aet/opt/anaconda3/envs/codeforecon/lib/python3.8/site-packages/jupyter_cache/executors/utils.py", line 51, in single_nb_execution
    executenb(
  File "/Users/aet/opt/anaconda3/envs/codeforecon/lib/python3.8/site-packages/nbclient/client.py", line 1087, in execute
    return NotebookClient(nb=nb, resources=resources, km=km, **kwargs).execute()
  File "/Users/aet/opt/anaconda3/envs/codeforecon/lib/python3.8/site-packages/nbclient/util.py", line 74, in wrapped
    return just_run(coro(*args, **kwargs))
  File "/Users/aet/opt/anaconda3/envs/codeforecon/lib/python3.8/site-packages/nbclient/util.py", line 53, in just_run
    return loop.run_until_complete(coro)
  File "/Users/aet/opt/anaconda3/envs/codeforecon/lib/python3.8/asyncio/base_events.py", line 616, in run_until_complete
    return future.result()
  File "/Users/aet/opt/anaconda3/envs/codeforecon/lib/python3.8/site-packages/nbclient/client.py", line 540, in async_execute
    await self.async_execute_cell(
  File "/Users/aet/opt/anaconda3/envs/codeforecon/lib/python3.8/site-packages/nbclient/client.py", line 832, in async_execute_cell
    self._check_raise_for_error(cell, exec_reply)
  File "/Users/aet/opt/anaconda3/envs/codeforecon/lib/python3.8/site-packages/nbclient/client.py", line 740, in _check_raise_for_error
    raise CellExecutionError.from_cell_and_msg(cell, exec_reply['content'])
nbclient.exceptions.CellExecutionError: An error occurred while executing the following cell:
------------------
df = xf.assign(string_col=df['string_col'].astype('string'),
               double_col=df['double_col'].astype('double'),
               category_col=df['category_col'].astype('category'),
               datetime_col=df['datetime_col'].astype('datetime64[ns]'),
               integer_col=df['integer_col'].astype('int'),
               bool_col=df['bool_col'].astype('bool'))
df.info()
------------------

[0;31m---------------------------------------------------------------------------[0m
[0;31mNameError[0m                                 Traceback (most recent call last)
[0;32m<ipython-input-9-d147e5f95493>[0m in [0;36m<module>[0;34m[0m
[0;32m----> 1[0;31m df = xf.assign(string_col=df['string_col'].astype('string'),
[0m[1;32m      2[0m                [0mdouble_col[0m[0;34m=[0m[0mdf[0m[0;34m[[0m[0;34m'double_col'[0m[0;34m][0m[0;34m.[0m[0mastype[0m[0;34m([0m[0;34m'double'[0m[0;34m)[0m[0;34m,[0m[0;34m[0m[0;34m[0m[0m
[1;32m      3[0m                [0mcategory_col[0m[0;34m=[0m[0mdf[0m[0;34m[[0m[0;34m'category_col'[0m[0;34m][0m[0;34m.[0m[0mastype[0m[0;34m([0m[0;34m'category'[0m[0;34m)[0m[0;34m,[0m[0;34m[0m[0;34m[0m[0m
[1;32m      4[0m                [0mdatetime_col[0m[0;34m=[0m[0mdf[0m[0;34m[[0m[0;34m'datetime_col'[0m[0;34m][0m[0;34m.[0m[0mastype[0m[0;34m([0m[0;34m'datetime64[ns]'[0m[0;34m)[0m[0;34m,[0m[0;34m[0m[0;34m[0m[0m
[1;32m      5[0m                [0minteger_col[0m[0;34m=[0m[0mdf[0m[0;34m[[0m[0;34m'integer_col'[0m[0;34m][0m[0;34m.[0m[0mastype[0m[0;34m([0m[0;34m'int'[0m[0;34m)[0m[0;34m,[0m[0;34m[0m[0;34m[0m[0m

[0;31mNameError[0m: name 'xf' is not defined
NameError: name 'xf' is not defined

