Traceback (most recent call last):
  File "/Users/aet/opt/anaconda3/envs/codeforecon/lib/python3.8/site-packages/jupyter_cache/executors/utils.py", line 51, in single_nb_execution
    executenb(
  File "/Users/aet/opt/anaconda3/envs/codeforecon/lib/python3.8/site-packages/nbclient/client.py", line 1087, in execute
    return NotebookClient(nb=nb, resources=resources, km=km, **kwargs).execute()
  File "/Users/aet/opt/anaconda3/envs/codeforecon/lib/python3.8/site-packages/nbclient/util.py", line 74, in wrapped
    return just_run(coro(*args, **kwargs))
  File "/Users/aet/opt/anaconda3/envs/codeforecon/lib/python3.8/site-packages/nbclient/util.py", line 53, in just_run
    return loop.run_until_complete(coro)
  File "/Users/aet/opt/anaconda3/envs/codeforecon/lib/python3.8/asyncio/base_events.py", line 616, in run_until_complete
    return future.result()
  File "/Users/aet/opt/anaconda3/envs/codeforecon/lib/python3.8/site-packages/nbclient/client.py", line 540, in async_execute
    await self.async_execute_cell(
  File "/Users/aet/opt/anaconda3/envs/codeforecon/lib/python3.8/site-packages/nbclient/client.py", line 832, in async_execute_cell
    self._check_raise_for_error(cell, exec_reply)
  File "/Users/aet/opt/anaconda3/envs/codeforecon/lib/python3.8/site-packages/nbclient/client.py", line 740, in _check_raise_for_error
    raise CellExecutionError.from_cell_and_msg(cell, exec_reply['content'])
nbclient.exceptions.CellExecutionError: An error occurred while executing the following cell:
------------------
# Plot a histogram of the data and fit a normal distribution
sns.distplot(data, bins=60, kde=False, fit=st.norm)
# Get the fitted parameters as computed by scipy
(est_loc, est_scale) = st.norm.fit(data)
plt.legend([f'Est. normal dist. ($\hat{{\mu}}=${est_loc:.2f} and $\hat{{\sigma}}=${est_scale:.2f} )',
            'Histogram'],
            loc='upper left', frameon=False)
fig = plt.figure()
res = st.probplot(data, plot=plt)
plt.show();
------------------

[0;31m---------------------------------------------------------------------------[0m
[0;31mNameError[0m                                 Traceback (most recent call last)
[0;32m<ipython-input-21-29e0e2db98ed>[0m in [0;36m<module>[0;34m[0m
[1;32m      1[0m [0;31m# Plot a histogram of the data and fit a normal distribution[0m[0;34m[0m[0;34m[0m[0;34m[0m[0m
[0;32m----> 2[0;31m [0msns[0m[0;34m.[0m[0mdistplot[0m[0;34m([0m[0mdata[0m[0;34m,[0m [0mbins[0m[0;34m=[0m[0;36m60[0m[0;34m,[0m [0mkde[0m[0;34m=[0m[0;32mFalse[0m[0;34m,[0m [0mfit[0m[0;34m=[0m[0mst[0m[0;34m.[0m[0mnorm[0m[0;34m)[0m[0;34m[0m[0;34m[0m[0m
[0m[1;32m      3[0m [0;31m# Get the fitted parameters as computed by scipy[0m[0;34m[0m[0;34m[0m[0;34m[0m[0m
[1;32m      4[0m [0;34m([0m[0mest_loc[0m[0;34m,[0m [0mest_scale[0m[0;34m)[0m [0;34m=[0m [0mst[0m[0;34m.[0m[0mnorm[0m[0;34m.[0m[0mfit[0m[0;34m([0m[0mdata[0m[0;34m)[0m[0;34m[0m[0;34m[0m[0m
[1;32m      5[0m plt.legend([f'Est. normal dist. ($\hat{{\mu}}=${est_loc:.2f} and $\hat{{\sigma}}=${est_scale:.2f} )',

[0;31mNameError[0m: name 'sns' is not defined
NameError: name 'sns' is not defined

