Traceback (most recent call last):
  File "/Users/aet/opt/anaconda3/envs/codeforecon/lib/python3.8/site-packages/jupyter_cache/executors/utils.py", line 51, in single_nb_execution
    executenb(
  File "/Users/aet/opt/anaconda3/envs/codeforecon/lib/python3.8/site-packages/nbclient/client.py", line 1087, in execute
    return NotebookClient(nb=nb, resources=resources, km=km, **kwargs).execute()
  File "/Users/aet/opt/anaconda3/envs/codeforecon/lib/python3.8/site-packages/nbclient/util.py", line 74, in wrapped
    return just_run(coro(*args, **kwargs))
  File "/Users/aet/opt/anaconda3/envs/codeforecon/lib/python3.8/site-packages/nbclient/util.py", line 53, in just_run
    return loop.run_until_complete(coro)
  File "/Users/aet/opt/anaconda3/envs/codeforecon/lib/python3.8/asyncio/base_events.py", line 616, in run_until_complete
    return future.result()
  File "/Users/aet/opt/anaconda3/envs/codeforecon/lib/python3.8/site-packages/nbclient/client.py", line 540, in async_execute
    await self.async_execute_cell(
  File "/Users/aet/opt/anaconda3/envs/codeforecon/lib/python3.8/site-packages/nbclient/client.py", line 832, in async_execute_cell
    self._check_raise_for_error(cell, exec_reply)
  File "/Users/aet/opt/anaconda3/envs/codeforecon/lib/python3.8/site-packages/nbclient/client.py", line 740, in _check_raise_for_error
    raise CellExecutionError.from_cell_and_msg(cell, exec_reply['content'])
nbclient.exceptions.CellExecutionError: An error occurred while executing the following cell:
------------------
import numpy as np
import pandas as pd
import seaborn as sns
import matplotlib.pyplot as plt
from plotnine import *
import altair as alt
import plotly.express as px
from vega_datasets import data
import os
from pathlib import Path

# Set seed for reproducibility
np.random.seed(10)
# Set max rows displayed for readability
pd.set_option("display.max_rows", 6)
# Plot settings
plt.style.use(
    "https://github.com/aeturrell/coding-for-economists/raw/main/plot_style.txt"
)
------------------

[0;31m---------------------------------------------------------------------------[0m
[0;31mModuleNotFoundError[0m                       Traceback (most recent call last)
[0;32m<ipython-input-1-9be131f124af>[0m in [0;36m<module>[0;34m[0m
[1;32m      5[0m [0;32mfrom[0m [0mplotnine[0m [0;32mimport[0m [0;34m*[0m[0;34m[0m[0;34m[0m[0m
[1;32m      6[0m [0;32mimport[0m [0maltair[0m [0;32mas[0m [0malt[0m[0;34m[0m[0;34m[0m[0m
[0;32m----> 7[0;31m [0;32mimport[0m [0mplotly[0m[0;34m.[0m[0mexpress[0m [0;32mas[0m [0mpx[0m[0;34m[0m[0;34m[0m[0m
[0m[1;32m      8[0m [0;32mfrom[0m [0mvega_datasets[0m [0;32mimport[0m [0mdata[0m[0;34m[0m[0;34m[0m[0m
[1;32m      9[0m [0;32mimport[0m [0mos[0m[0;34m[0m[0;34m[0m[0m

[0;31mModuleNotFoundError[0m: No module named 'plotly'
ModuleNotFoundError: No module named 'plotly'

